Workbook

Sheet Summary
A1: Workday, Inc. (WDAY) — the answer block
A3: Current price | B3: $129.34
A4: Shares outstanding (M) | B4: 257
A5: Diluted shares FY26 (M) | B5: 268
A6: Market cap ($B) | B6: 33.24
A7: EV ($B) | B7: 31.62
A8: Net cash ($B) — incl. ~$834M op-lease liab in debt | B8: 1.62
A10: FY26 revenue ($B) | B10: 9.55
A11: FY26 FCF ($B) | B11: 2.78
A12: FY26 owner FCF (FCF − SBC, $B) | B12: 1.15
A13: FY26 SBC ($B) | B13: 1.63
A14: FY26 12-mo sub backlog ($B) | B14: 8.83
A15: FY26 total sub backlog ($B) | B15: 28.1
A17: Prob-weighted FY29 TSR (3yr) | B17: +111.6%
A18: Prob-weighted FY30 TSR (4yr) | B18: +147.9%
A20: Scenario FY29 TSR (3-year)
A21: Scenario | B21: Prob | C21: Terminal $ | D21: Price Δ $ | E21: Cum Div $/sh | F21: Buyback $$M | G21: TSR % | H21: IRR %
A22: Good AI | B22: 0.35 | C22: 577.92 | D22: 448.58 | E22: 0 | F22: 5652 | G22: 3.468 | H22: 0.647
A23: Runs For Cash | B23: 0.35 | C23: 125.26 | D23: -4.08 | E23: 11.78 | F23: 6617 | G23: 0.06 | H23: 0.019
A24: What Goes Wrong | B24: 0.3 | C24: 74.88 | D24: -54.46 | E24: 3.39 | F24: 2970 | G24: -0.395 | H24: -0.154
A26: Scenario FY30 TSR (4-year)
A27: Scenario | B27: Prob | C27: Terminal $ | D27: Price Δ $ | E27: Cum Div $/sh | F27: Buyback $$M | G27: TSR % | H27: IRR %
A28: Good AI | B28: 0.35 | C28: 708.15 | D28: 578.81 | E28: 0 | F28: 10044 | G28: 4.475 | H28: 0.53
A29: Runs For Cash | B29: 0.35 | C29: 124.93 | D29: -4.41 | E29: 18.94 | F29: 9556 | G29: 0.112 | H29: 0.027
A30: What Goes Wrong | B30: 0.3 | C30: 69.15 | D30: -60.19 | E30: 5.48 | F30: 3841 | G30: -0.423 | H30: -0.128
A32: Headline math (FY29)
A33: Good AI | B33: 28x FCF on $20.35 FY29 FCF/share growing 18% = $578 + $22 cum cap return = TSR +347%
A34: Runs For Cash | B34: 9x FCF on $13.77 FY29 FCF/share growing -7% = $125 + $38 cum cap return = TSR +6%
A35: What Goes Wrong | B35: 7x FCF on $8.38 FY29 FCF/share growing -9% = $75 + $15 cum cap return = TSR -40%

Sheet Assumptions
A1: Workday, Inc. (WDAY) — model assumptions
A3: Anchor inputs (May 2026)
A4: Current price | B4: 129.34
A5: Shares outstanding (M) | B5: 257
A6: Shares diluted FY26 (M) | B6: 268
A7: Net cash ($B) | B7: 1.62
A9: Driver matrix — FY27E to FY30E
A10: Driver | B10: Scenario | C10: FY27 | D10: FY28 | E10: FY29 | F10: FY30
A11: Revenue growth % | B11: AI Winner | C11: 0.1056 | D11: 0.1667 | E11: 0.1843 | F11: 0.1671
A12: Revenue growth % | B12: Run For Cash | C12: 0.0252 | D12: -0.0328 | E12: -0.0687 | F12: -0.08
A13: Revenue growth % | B13: Bear | C13: -0.0215 | D13: -0.0795 | E13: -0.0932 | F13: -0.1015
A15: Backlog growth % | B15: AI Winner | C15: 0.16 | D15: 0.1801 | E15: 0.19 | F15: 0.16
A16: Backlog growth % | B16: Run For Cash | C16: -0.04 | D16: -0.09 | E16: -0.1 | F16: -0.0801
A17: Backlog growth % | B17: Bear | C17: -0.05 | D17: -0.1 | E17: -0.11 | F17: -0.0899
A19: Cost of rev (% rev) | B19: AI Winner | C19: 0.2541 | D19: 0.2502 | E19: 0.2444 | F19: 0.2344
A20: Cost of rev (% rev) | B20: Run For Cash | C20: 0.255 | D20: 0.255 | E20: 0.2551 | F20: 0.2525
A21: Cost of rev (% rev) | B21: Bear | C21: 0.2556 | D21: 0.2562 | E21: 0.2581 | F21: 0.2578
A23: R&D (% rev) | B23: AI Winner | C23: 0.26 | D23: 0.25 | E23: 0.24 | F23: 0.23
A24: R&D (% rev) | B24: Run For Cash | C24: 0.24 | D24: 0.2 | E24: 0.16 | F24: 0.13
A25: R&D (% rev) | B25: Bear | C25: 0.26 | D25: 0.23 | E25: 0.1999 | F25: 0.18
... A45: Buyback (%/yr) | B45: Bear | C45: 0.025 | D45: 0.0348 | E45: 0.04 | F45: 0.0401
A47: Exit ARR multiple | B47: AI Winner | C47: 10
B48: Run For Cash | C48: 3.5
B49: Bear | C49: 2.8
A50: Exit FCF multiple | B50: AI Winner | C50: 28
B51: Run For Cash | C51: 9
B52: Bear | C52: 7
A53: Probability | B53: AI Winner | C53: 0.35
B54: Run For Cash | C54: 0.35
B55: Bear | C55: 0.3
A58: Unit economics — HCM seats × PEPM / Financials customers × ARPC
A59: Historical (FY18-FY26)
A60: $/seats/customers | B60: FY2018 | C60: FY2019 | D60: FY2020 | E60: FY2021 | F60: FY2022 | G60: FY2023 | H60: FY2024 | I60: FY2025 | J60: FY2026
A61: HCM seats (M) | B61: 18.5 | C61: 22 | D61: 26 | E61: 29.5 | F61: 34 | G61: 40 | H61: 47 | I61: 53 | J61: 60
A62: HCM PEPM ($/mo) | B62: 8.74 | C62: 9.44 | D62: 9.8 | E62: 9.88 | F62: 10.17 | G62: 10.29 | H62: 9.13 | I62: 9.24 | J62: 7.82
A63: HCM revenue implied ($M) | B63: 1940 | C63: 2492 | D63: 3058 | E63: 3498 | F63: 4149 | G63: 4939 | H63: 5149 | I63: 5877 | J63: 5630
A64: Financials customers (#) | B64: 380 | C64: 490 | D64: 620 | E64: 770 | F64: 960 | G64: 1200 | H64: 1500 | I64: 1800 | J64: 2150
A65: Financials ARPC ($k/yr) | B65: 405 | C65: 462 | D65: 528 | E65: 599 | F65: 678 | G65: 808 | H65: 969 | I65: 965 | J65: 1304
A66: Financials revenue implied ($M) | B66: 154 | C66: 226 | D66: 327 | E66: 461 | F66: 651 | G66: 970 | H66: 1454 | I66: 1737 | J66: 2804
A68: Forecast (FY27-FY30) per scenario
...

Sheet Historicals
A1: WDAY historicals (FY21-FY26)
A3: $M | B3: FY2021 | C3: FY2022 | D3: FY2023 | E3: FY2024 | F3: FY2025 | G3: FY2026
A4: Income Statement
A5: Revenue | B5: 4318 | C5: 5139 | D5: 6216 | E5: 7259 | F5: 8446 | G5: 9552
A6: Cost of revenue | B6: 1198.1 | C6: 1428 | D6: 1750 | E6: 1771 | F6: 2153 | G6: 2624
A7: Gross profit | B7: 3119.9 | C7: 3711 | D7: 4466 | E7: 5488 | F7: 6293 | G7: 6928
A8: R&D | B8: 1721.2 | C8: 1879 | D8: 2247 | E8: 2464 | F8: 2626 | G8: 2679
A9: S&M | B9: 1233.2 | C9: 1462 | D9: 1842 | E9: 2139 | F9: 2432 | G9: 2616
A10: G&A | B10: 414.1 | C10: 486 | D10: 599 | E10: 702 | F10: 820 | G10: 912
A11: Operating income | B11: -248.6 | C11: -116 | D11: -222 | E11: 183 | F11: 415 | G11: 721
A12: Net income (GAAP) | B12: -282.4 | C12: 29 | D12: -367 | E12: 1381 | F12: 526 | G12: 693
A14: Cash Flow
A15: Cash from operations | B15: 1268.4 | C15: 1651 | D15: 1657 | E15: 2149 | F15: 2461 | G15: 2939
A16: Capex | D16: 364 | E16: 232 | F16: 269 | G16: 162
A17: Free cash flow | B17: 1268.4 | C17: 1651 | D17: 1293 | E17: 1917 | F17: 2192 | G17: 2777
A18: SBC (memo) | B18: 1004.9 | C18: 1101 | D18: 1295 | E18: 1416 | F18: 1519 | G18: 1626
A19: FCF − SBC | B19: 263.5 | C19: 550 | D19: -2 | E19: 501 | F19: 673 | G19: 1151
A20: Diluted shares (M) | B20: 237 | C20: 254 | D20: 254.8 | E20: 265.3 | F20: 269.2 | G20: 268.1

Sheet Forecast_AI
A1: WDAY forecast — AI Winner
A3: Period | B3: Actual | C3: Actual | D3: Actual | E3: Actual | F3: Actual | G3: Actual | H3: Forecast | I3: Forecast | J3: Forecast | K3: Forecast | M3: CAGR | N3: CAGR
A4: $M unless noted | B4: FY21A | C4: FY22A | D4: FY23A | E4: FY24A | F4: FY25A | G4: FY26A | H4: FY27E | I4: FY28E | J4: FY29E | K4: FY30E | M4: CAGR FY21-25 | N4: CAGR FY26-30
A5: Drivers (from Assumptions tab)
A6: Revenue growth % | H6: =Assumptions!C11 | I6: =Assumptions!D11 | J6: =Assumptions!E11 | K6: =Assumptions!F11
A7: Backlog growth % | H7: =Assumptions!C15 | I7: =Assumptions!D15 | J7: =Assumptions!E15 | K7: =Assumptions!F15
A8: Cost of rev (% rev) | H8: =Assumptions!C19 | I8: =Assumptions!D19 | J8: =Assumptions!E19 | K8: =Assumptions!F19
A9: R&D (% rev) | H9: =Assumptions!C23 | I9: =Assumptions!D23 | J9: =Assumptions!E23 | K9: =Assumptions!F23
A10: S&M (% rev) | H10: =Assumptions!C27 | I10: =Assumptions!D27 | J10: =Assumptions!E27 | K10: =Assumptions!F27
A11: G&A (% rev) | H11: =Assumptions!C31 | I11: =Assumptions!D31 | J11: =Assumptions!E31 | K11: =Assumptions!F31
A12: SBC (% rev) | H12: =Assumptions!C35 | I12: =Assumptions!D35 | J12: =Assumptions!E35 | K12: =Assumptions!F35
A13: CFO margin | H13: =Assumptions!C39 | I13: =Assumptions!D39 | J13: =Assumptions!E39 | K13: =Assumptions!F39
A14: Buyback (%/yr) | H14: =Assumptions!C43 | I14: =Assumptions!D43 | J14: =Assumptions!E43 | K14: =Assumptions!F43
A16: Income Statement
A17: Revenue | B17: 4318 | C17: 5139 | D17: 6216 | E17: 7259 | F17: 8446 | G17: 9552 | H17: =G17*(1+Assumptions!C11) | I17: =H17*(1+Assumptions!D11) | J17: =I17*(1+Assumptions!E11) | K17: =J17*(1+Assumptions!F11) | M17: =IFERROR(IF(OR(B17<=0,F17<=0),"N/M",(F17/B17)^(1/4)-1), "N/M") | N17: =IFERROR(IF(OR(G17<=0,K17<=0),"N/M",(K17/G17)^(1/4)-1), "N/M")
A18: Cost of revenue | B18: 1198.1 | C18: 1428 | D18: 1750 | E18: 1771 | F18: 2153 | G18: 2624 | H18: =H17*Assumptions!C19 | I18: =I17*Assumptions!D19 | J18: =J17*Assumptions!E19 | K18: =K17*Assumptions!F19 | M18: =IFERROR(IF(OR(B18<=0,F18<=0),"N/M",(F18/B18)^(1/4)-1), "N/M") | N18: =IFERROR(IF(OR(G18<=0,K18<=0),"N/M",(K18/G18)^(1/4)-1), "N/M")
A19: Gross profit | B19: =B17-B18 | C19: =C17-C18 | D19: =D17-D18 | E19: =E17-E18 | F19: =F17-F18 | G19: =G17-G18 | H19: =H17-H18 | I19: =I17-I18 | ... K19: =K17-K18 | M19: =IFERROR(IF(OR(B19<=0,F19<=0),"N/M",(F19/B19)^(1/4)-1), "N/M") | N19: =IFERROR(IF(OR(G19<=0,K19<=0),"N/M",(K19/G19)^(1/4)-1), "N/M")
A20: R&D | B20: 1721.2 | C20: 1879 | D20: 2247 | E20: 2464 | F20: 2626 | G20: 2679 | H20: =H17*Assumptions!C23 | I20: =I17*Assumptions!D23 | J20: =J17*Assumptions!E23 | K20: =K17*Assumptions!F23 | M20: =IFERROR(IF(OR(B20<=0,F20<=0),"N/M",(F20/B20)^(1/4)-1), "N/M") | N20: =IFERROR(IF(OR(G20<=0,K20<=0),"N/M",(K20/G20)^(1/4)-1), "N/M")
A21: S&M | B21: 1233.2 | C21: 1462 | D21: 1842 | E21: 2139 | F21: 2432 | G21: 2616 | H21: =H17*Assumptions!C27 | I21: =I17*Assumptions!D27 | J21: =J17*Assumptions!E27 | K21: =K17*Assumptions!F27 | M21: =IFERROR(IF(OR(B21<=0,F21<=0),"N/M",(F21/B21)^(1/4)-1), "N/M") | N21: =IFERROR(IF(OR(G21<=0,K21<=0),"N/M",(K21/G21)^(1/4)-1), "N/M")
A22: G&A | B22: 414.1 | C22: 486 | D22: 599 | E22: 702 | F22: 820 | G22: 912 | H22: =H17*Assumptions!C31 | I22: =I17*Assumptions!D31 | J22: =J17*Assumptions!E31 | K22: =K17*Assumptions!F31 | M22: =IFERROR(IF(OR(B22<=0,F22<=0),"N/M",(F22/B22)^(1/4)-1), "N/M") | N22: =IFERROR(IF(OR(G22<=0,K22<=0),"N/M",(K22/G22)^(1/4)-1), "N/M")
A23: Operating income | B23: -248.6 | C23: -116 | D23: -222 | E23: 183 | F23: 415 | G23: 721 | H23: =H19-H20-H21-H22-280 | I23: =I19-I20-I21-I22-300 | J23: =J19-J20-J21-J22-320 | K23: =K19-K20-K21-K22-340 | M23: =IFERROR(IF(OR(B23<=0,F23<=0),"N/M",(F23/B23)^(1/4)-1), "N/M") | N23: =IFERROR(IF(OR(G23<=0,K23<=0),"N/M",(K23/G23)^(1/4)-1), "N/M")
A24: Operating margin % | B24: =IFERROR(B23/B17,"") | C24: =IFERROR(C23/C17,"") | D24: =IFERROR(D23/D17,"") | E24: =IFERROR(E23/E17,"") | F24: =IFERROR(F23/F17,"") | G24: =IFERROR(G23/G17,"") | H24: =IFERROR(H23/H17,"") | I24: =IFERROR(I23/I17,"") | ... K24: =IFERROR(K23/K17,"") | M24: =IFERROR(F24-B24, "") | N24: =IFERROR(K24-G24, "")
A25: Net income (GAAP) | B25: -282.4 | C25: 29 | D25: -367 | E25: 1381 | F25: 526 | G25: 693 | M25: =IFERROR(IF(OR(B25<=0,F25<=0),"N/M",(F25/B25)^(1/4)-1), "N/M") | N25: =IFERROR(IF(OR(G25<=0,K25<=0),"N/M",(K25/G25)^(1/4)-1), "N/M")
A27: Cash Flow
A28: Cash from operations | B28: 1268.4 | C28: 1651 | D28: 1657 | E28: 2149 | F28: 2461 | G28: 2939 | H28: =H17*Assumptions!C39 | I28: =I17*Assumptions!D39 | J28: =J17*Assumptions!E39 | K28: =K17*Assumptions!F39 | M28: =IFERROR(IF(OR(B28<=0,F28<=0),"N/M",(F28/B28)^(1/4)-1), "N/M") | N28: =IFERROR(IF(OR(G28<=0,K28<=0),"N/M",(K28/G28)^(1/4)-1), "N/M")
A29: Capex (~2% rev) | D29: 364 | E29: 232 | F29: 269 | G29: 162 | H29: =H17*0.02 | I29: =I17*0.02 | J29: =J17*0.02 | K29: =K17*0.02 | M29: =IFERROR(IF(OR(B29<=0,F29<=0),"N/M",(F29/B29)^(1/4)-1), "N/M") | N29: =IFERROR(IF(OR(G29<=0,K29<=0),"N/M",(K29/G29)^(1/4)-1), "N/M")
A30: Free cash flow | B30: =IFERROR(B28-B29,B28) | C30: =IFERROR(C28-C29,C28) | D30: =IFERROR(D28-D29,D28) | E30: =IFERROR(E28-E29,E28) | F30: =IFERROR(F28-F29,F28) | G30: =IFERROR(G28-G29,G28) | H30: =IFERROR(H28-H29,H28) | I30: =IFERROR(I28-I29,I28) | ... K30: =IFERROR(K28-K29,K28) | M30: =IFERROR(IF(OR(B30<=0,F30<=0),"N/M",(F30/B30)^(1/4)-1), "N/M") | N30: =IFERROR(IF(OR(G30<=0,K30<=0),"N/M",(K30/G30)^(1/4)-1), "N/M")
A31: SBC | B31: 1004.9 | C31: 1101 | D31: 1295 | E31: 1416 | F31: 1519 | G31: 1626 | H31: =H17*Assumptions!C35 | I31: =I17*Assumptions!D35 | J31: =J17*Assumptions!E35 | K31: =K17*Assumptions!F35 | M31: =IFERROR(IF(OR(B31<=0,F31<=0),"N/M",(F31/B31)^(1/4)-1), "N/M") | N31: =IFERROR(IF(OR(G31<=0,K31<=0),"N/M",(K31/G31)^(1/4)-1), "N/M")
A32: FCF − SBC | B32: =B30-B31 | C32: =C30-C31 | D32: =D30-D31 | E32: =E30-E31 | F32: =F30-F31 | G32: =G30-G31 | H32: =H30-H31 | I32: =I30-I31 | ... K32: =K30-K31 | M32: =IFERROR(IF(OR(B32<=0,F32<=0),"N/M",(F32/B32)^(1/4)-1), "N/M") | N32: =IFERROR(IF(OR(G32<=0,K32<=0),"N/M",(K32/G32)^(1/4)-1), "N/M")
A34: Per-share
A35: Diluted shares (M) | B35: 237 | C35: 254 | D35: 254.8 | E35: 265.3 | F35: 269.2 | G35: 268.1 | H35: =G35*(1-Assumptions!C43) | I35: =H35*(1-Assumptions!D43) | J35: =I35*(1-Assumptions!E43) | K35: =J35*(1-Assumptions!F43) | M35: =IFERROR(IF(OR(B35<=0,F35<=0),"N/M",(F35/B35)^(1/4)-1), "N/M") | N35: =IFERROR(IF(OR(G35<=0,K35<=0),"N/M",(K35/G35)^(1/4)-1), "N/M")
A36: FCF / share | B36: =IFERROR(B30/B35,"") | C36: =IFERROR(C30/C35,"") | D36: =IFERROR(D30/D35,"") | E36: =IFERROR(E30/E35,"") | F36: =IFERROR(F30/F35,"") | G36: =IFERROR(G30/G35,"") | H36: =IFERROR(H30/H35,"") | I36: =IFERROR(I30/I35,"") | ... K36: =IFERROR(K30/K35,"") | M36: =IFERROR(IF(OR(B36<=0,F36<=0),"N/M",(F36/B36)^(1/4)-1), "N/M") | N36: =IFERROR(IF(OR(G36<=0,K36<=0),"N/M",(K36/G36)^(1/4)-1), "N/M")
A37: 12-mo backlog ($M) | E37: 6602 | F37: 7631 | G37: 8833 | H37: =G37*(1+Assumptions!C15) | I37: =H37*(1+Assumptions!D15) | J37: =I37*(1+Assumptions!E15) | K37: =J37*(1+Assumptions!F15) | M37: =IFERROR(IF(OR(B37<=0,F37<=0),"N/M",(F37/B37)^(1/4)-1), "N/M") | N37: =IFERROR(IF(OR(G37<=0,K37<=0),"N/M",(K37/G37)^(1/4)-1), "N/M")
A39: Valuation (terminal = FY30)
A40: Target ($/sh, ARR-lens) | K40: =(Assumptions!C47*K37+Assumptions!B7*1000)/K35
A41: Target ($/sh, FCF-lens) | K41: =(Assumptions!C50*K30+Assumptions!B7*1000)/K35
A42: Target (blended) | K42: =AVERAGE(K40,K41)

Sheet Forecast_Cash
A1: WDAY forecast — Run For Cash
A3: Period | B3: Actual | C3: Actual | D3: Actual | E3: Actual | F3: Actual | G3: Actual | H3: Forecast | I3: Forecast | J3: Forecast | K3: Forecast | M3: CAGR | N3: CAGR
A4: $M unless noted | B4: FY21A | C4: FY22A | D4: FY23A | E4: FY24A | F4: FY25A | G4: FY26A | H4: FY27E | I4: FY28E | J4: FY29E | K4: FY30E | M4: CAGR FY21-25 | N4: CAGR FY26-30
A5: Drivers (from Assumptions tab)
A6: Revenue growth % | H6: =Assumptions!C12 | I6: =Assumptions!D12 | J6: =Assumptions!E12 | K6: =Assumptions!F12
A7: Backlog growth % | H7: =Assumptions!C16 | I7: =Assumptions!D16 | J7: =Assumptions!E16 | K7: =Assumptions!F16
A8: Cost of rev (% rev) | H8: =Assumptions!C20 | I8: =Assumptions!D20 | J8: =Assumptions!E20 | K8: =Assumptions!F20
A9: R&D (% rev) | H9: =Assumptions!C24 | I9: =Assumptions!D24 | J9: =Assumptions!E24 | K9: =Assumptions!F24
A10: S&M (% rev) | H10: =Assumptions!C28 | I10: =Assumptions!D28 | J10: =Assumptions!E28 | K10: =Assumptions!F28
A11: G&A (% rev) | H11: =Assumptions!C32 | I11: =Assumptions!D32 | J11: =Assumptions!E32 | K11: =Assumptions!F32
A12: SBC (% rev) | H12: =Assumptions!C36 | I12: =Assumptions!D36 | J12: =Assumptions!E36 | K12: =Assumptions!F36
A13: CFO margin | H13: =Assumptions!C40 | I13: =Assumptions!D40 | J13: =Assumptions!E40 | K13: =Assumptions!F40
A14: Buyback (%/yr) | H14: =Assumptions!C44 | I14: =Assumptions!D44 | J14: =Assumptions!E44 | K14: =Assumptions!F44
A16: Income Statement
A17: Revenue | B17: 4318 | C17: 5139 | D17: 6216 | E17: 7259 | F17: 8446 | G17: 9552 | H17: =G17*(1+Assumptions!C12) | I17: =H17*(1+Assumptions!D12) | J17: =I17*(1+Assumptions!E12) | K17: =J17*(1+Assumptions!F12) | M17: =IFERROR(IF(OR(B17<=0,F17<=0),"N/M",(F17/B17)^(1/4)-1), "N/M") | N17: =IFERROR(IF(OR(G17<=0,K17<=0),"N/M",(K17/G17)^(1/4)-1), "N/M")
A18: Cost of revenue | B18: 1198.1 | C18: 1428 | D18: 1750 | E18: 1771 | F18: 2153 | G18: 2624 | H18: =H17*Assumptions!C20 | I18: =I17*Assumptions!D20 | J18: =J17*Assumptions!E20 | K18: =K17*Assumptions!F20 | M18: =IFERROR(IF(OR(B18<=0,F18<=0),"N/M",(F18/B18)^(1/4)-1), "N/M") | N18: =IFERROR(IF(OR(G18<=0,K18<=0),"N/M",(K18/G18)^(1/4)-1), "N/M")
A19: Gross profit | B19: =B17-B18 | C19: =C17-C18 | D19: =D17-D18 | E19: =E17-E18 | F19: =F17-F18 | G19: =G17-G18 | H19: =H17-H18 | I19: =I17-I18 | ... K19: =K17-K18 | M19: =IFERROR(IF(OR(B19<=0,F19<=0),"N/M",(F19/B19)^(1/4)-1), "N/M") | N19: =IFERROR(IF(OR(G19<=0,K19<=0),"N/M",(K19/G19)^(1/4)-1), "N/M")
A20: R&D | B20: 1721.2 | C20: 1879 | D20: 2247 | E20: 2464 | F20: 2626 | G20: 2679 | H20: =H17*Assumptions!C24 | I20: =I17*Assumptions!D24 | J20: =J17*Assumptions!E24 | K20: =K17*Assumptions!F24 | M20: =IFERROR(IF(OR(B20<=0,F20<=0),"N/M",(F20/B20)^(1/4)-1), "N/M") | N20: =IFERROR(IF(OR(G20<=0,K20<=0),"N/M",(K20/G20)^(1/4)-1), "N/M")
A21: S&M | B21: 1233.2 | C21: 1462 | D21: 1842 | E21: 2139 | F21: 2432 | G21: 2616 | H21: =H17*Assumptions!C28 | I21: =I17*Assumptions!D28 | J21: =J17*Assumptions!E28 | K21: =K17*Assumptions!F28 | M21: =IFERROR(IF(OR(B21<=0,F21<=0),"N/M",(F21/B21)^(1/4)-1), "N/M") | N21: =IFERROR(IF(OR(G21<=0,K21<=0),"N/M",(K21/G21)^(1/4)-1), "N/M")
A22: G&A | B22: 414.1 | C22: 486 | D22: 599 | E22: 702 | F22: 820 | G22: 912 | H22: =H17*Assumptions!C32 | I22: =I17*Assumptions!D32 | J22: =J17*Assumptions!E32 | K22: =K17*Assumptions!F32 | M22: =IFERROR(IF(OR(B22<=0,F22<=0),"N/M",(F22/B22)^(1/4)-1), "N/M") | N22: =IFERROR(IF(OR(G22<=0,K22<=0),"N/M",(K22/G22)^(1/4)-1), "N/M")
A23: Operating income | B23: -248.6 | C23: -116 | D23: -222 | E23: 183 | F23: 415 | G23: 721 | H23: =H19-H20-H21-H22-280 | I23: =I19-I20-I21-I22-300 | J23: =J19-J20-J21-J22-320 | K23: =K19-K20-K21-K22-340 | M23: =IFERROR(IF(OR(B23<=0,F23<=0),"N/M",(F23/B23)^(1/4)-1), "N/M") | N23: =IFERROR(IF(OR(G23<=0,K23<=0),"N/M",(K23/G23)^(1/4)-1), "N/M")
A24: Operating margin % | B24: =IFERROR(B23/B17,"") | C24: =IFERROR(C23/C17,"") | D24: =IFERROR(D23/D17,"") | E24: =IFERROR(E23/E17,"") | F24: =IFERROR(F23/F17,"") | G24: =IFERROR(G23/G17,"") | H24: =IFERROR(H23/H17,"") | I24: =IFERROR(I23/I17,"") | ... K24: =IFERROR(K23/K17,"") | M24: =IFERROR(F24-B24, "") | N24: =IFERROR(K24-G24, "")
A25: Net income (GAAP) | B25: -282.4 | C25: 29 | D25: -367 | E25: 1381 | F25: 526 | G25: 693 | M25: =IFERROR(IF(OR(B25<=0,F25<=0),"N/M",(F25/B25)^(1/4)-1), "N/M") | N25: =IFERROR(IF(OR(G25<=0,K25<=0),"N/M",(K25/G25)^(1/4)-1), "N/M")
A27: Cash Flow
A28: Cash from operations | B28: 1268.4 | C28: 1651 | D28: 1657 | E28: 2149 | F28: 2461 | G28: 2939 | H28: =H17*Assumptions!C40 | I28: =I17*Assumptions!D40 | J28: =J17*Assumptions!E40 | K28: =K17*Assumptions!F40 | M28: =IFERROR(IF(OR(B28<=0,F28<=0),"N/M",(F28/B28)^(1/4)-1), "N/M") | N28: =IFERROR(IF(OR(G28<=0,K28<=0),"N/M",(K28/G28)^(1/4)-1), "N/M")
A29: Capex (~2% rev) | D29: 364 | E29: 232 | F29: 269 | G29: 162 | H29: =H17*0.02 | I29: =I17*0.02 | J29: =J17*0.02 | K29: =K17*0.02 | M29: =IFERROR(IF(OR(B29<=0,F29<=0),"N/M",(F29/B29)^(1/4)-1), "N/M") | N29: =IFERROR(IF(OR(G29<=0,K29<=0),"N/M",(K29/G29)^(1/4)-1), "N/M")
A30: Free cash flow | B30: =IFERROR(B28-B29,B28) | C30: =IFERROR(C28-C29,C28) | D30: =IFERROR(D28-D29,D28) | E30: =IFERROR(E28-E29,E28) | F30: =IFERROR(F28-F29,F28) | G30: =IFERROR(G28-G29,G28) | H30: =IFERROR(H28-H29,H28) | I30: =IFERROR(I28-I29,I28) | ... K30: =IFERROR(K28-K29,K28) | M30: =IFERROR(IF(OR(B30<=0,F30<=0),"N/M",(F30/B30)^(1/4)-1), "N/M") | N30: =IFERROR(IF(OR(G30<=0,K30<=0),"N/M",(K30/G30)^(1/4)-1), "N/M")
A31: SBC | B31: 1004.9 | C31: 1101 | D31: 1295 | E31: 1416 | F31: 1519 | G31: 1626 | H31: =H17*Assumptions!C36 | I31: =I17*Assumptions!D36 | J31: =J17*Assumptions!E36 | K31: =K17*Assumptions!F36 | M31: =IFERROR(IF(OR(B31<=0,F31<=0),"N/M",(F31/B31)^(1/4)-1), "N/M") | N31: =IFERROR(IF(OR(G31<=0,K31<=0),"N/M",(K31/G31)^(1/4)-1), "N/M")
A32: FCF − SBC | B32: =B30-B31 | C32: =C30-C31 | D32: =D30-D31 | E32: =E30-E31 | F32: =F30-F31 | G32: =G30-G31 | H32: =H30-H31 | I32: =I30-I31 | ... K32: =K30-K31 | M32: =IFERROR(IF(OR(B32<=0,F32<=0),"N/M",(F32/B32)^(1/4)-1), "N/M") | N32: =IFERROR(IF(OR(G32<=0,K32<=0),"N/M",(K32/G32)^(1/4)-1), "N/M")
A34: Per-share
A35: Diluted shares (M) | B35: 237 | C35: 254 | D35: 254.8 | E35: 265.3 | F35: 269.2 | G35: 268.1 | H35: =G35*(1-Assumptions!C44) | I35: =H35*(1-Assumptions!D44) | J35: =I35*(1-Assumptions!E44) | K35: =J35*(1-Assumptions!F44) | M35: =IFERROR(IF(OR(B35<=0,F35<=0),"N/M",(F35/B35)^(1/4)-1), "N/M") | N35: =IFERROR(IF(OR(G35<=0,K35<=0),"N/M",(K35/G35)^(1/4)-1), "N/M")
A36: FCF / share | B36: =IFERROR(B30/B35,"") | C36: =IFERROR(C30/C35,"") | D36: =IFERROR(D30/D35,"") | E36: =IFERROR(E30/E35,"") | F36: =IFERROR(F30/F35,"") | G36: =IFERROR(G30/G35,"") | H36: =IFERROR(H30/H35,"") | I36: =IFERROR(I30/I35,"") | ... K36: =IFERROR(K30/K35,"") | M36: =IFERROR(IF(OR(B36<=0,F36<=0),"N/M",(F36/B36)^(1/4)-1), "N/M") | N36: =IFERROR(IF(OR(G36<=0,K36<=0),"N/M",(K36/G36)^(1/4)-1), "N/M")
A37: 12-mo backlog ($M) | E37: 6602 | F37: 7631 | G37: 8833 | H37: =G37*(1+Assumptions!C16) | I37: =H37*(1+Assumptions!D16) | J37: =I37*(1+Assumptions!E16) | K37: =J37*(1+Assumptions!F16) | M37: =IFERROR(IF(OR(B37<=0,F37<=0),"N/M",(F37/B37)^(1/4)-1), "N/M") | N37: =IFERROR(IF(OR(G37<=0,K37<=0),"N/M",(K37/G37)^(1/4)-1), "N/M")
A39: Valuation (terminal = FY30)
A40: Target ($/sh, ARR-lens) | K40: =(Assumptions!C48*K37+Assumptions!B7*1000)/K35
A41: Target ($/sh, FCF-lens) | K41: =(Assumptions!C51*K30+Assumptions!B7*1000)/K35
A42: Target (blended) | K42: =AVERAGE(K40,K41)

Sheet Forecast_Bear
A1: WDAY forecast — Bear
A3: Period | B3: Actual | C3: Actual | D3: Actual | E3: Actual | F3: Actual | G3: Actual | H3: Forecast | I3: Forecast | J3: Forecast | K3: Forecast | M3: CAGR | N3: CAGR
A4: $M unless noted | B4: FY21A | C4: FY22A | D4: FY23A | E4: FY24A | F4: FY25A | G4: FY26A | H4: FY27E | I4: FY28E | J4: FY29E | K4: FY30E | M4: CAGR FY21-25 | N4: CAGR FY26-30
A5: Drivers (from Assumptions tab)
A6: Revenue growth % | H6: =Assumptions!C13 | I6: =Assumptions!D13 | J6: =Assumptions!E13 | K6: =Assumptions!F13
A7: Backlog growth % | H7: =Assumptions!C17 | I7: =Assumptions!D17 | J7: =Assumptions!E17 | K7: =Assumptions!F17
A8: Cost of rev (% rev) | H8: =Assumptions!C21 | I8: =Assumptions!D21 | J8: =Assumptions!E21 | K8: =Assumptions!F21
A9: R&D (% rev) | H9: =Assumptions!C25 | I9: =Assumptions!D25 | J9: =Assumptions!E25 | K9: =Assumptions!F25
A10: S&M (% rev) | H10: =Assumptions!C29 | I10: =Assumptions!D29 | J10: =Assumptions!E29 | K10: =Assumptions!F29
A11: G&A (% rev) | H11: =Assumptions!C33 | I11: =Assumptions!D33 | J11: =Assumptions!E33 | K11: =Assumptions!F33
A12: SBC (% rev) | H12: =Assumptions!C37 | I12: =Assumptions!D37 | J12: =Assumptions!E37 | K12: =Assumptions!F37
A13: CFO margin | H13: =Assumptions!C41 | I13: =Assumptions!D41 | J13: =Assumptions!E41 | K13: =Assumptions!F41
A14: Buyback (%/yr) | H14: =Assumptions!C45 | I14: =Assumptions!D45 | J14: =Assumptions!E45 | K14: =Assumptions!F45
A16: Income Statement
A17: Revenue | B17: 4318 | C17: 5139 | D17: 6216 | E17: 7259 | F17: 8446 | G17: 9552 | H17: =G17*(1+Assumptions!C13) | I17: =H17*(1+Assumptions!D13) | J17: =I17*(1+Assumptions!E13) | K17: =J17*(1+Assumptions!F13) | M17: =IFERROR(IF(OR(B17<=0,F17<=0),"N/M",(F17/B17)^(1/4)-1), "N/M") | N17: =IFERROR(IF(OR(G17<=0,K17<=0),"N/M",(K17/G17)^(1/4)-1), "N/M")
A18: Cost of revenue | B18: 1198.1 | C18: 1428 | D18: 1750 | E18: 1771 | F18: 2153 | G18: 2624 | H18: =H17*Assumptions!C21 | I18: =I17*Assumptions!D21 | J18: =J17*Assumptions!E21 | K18: =K17*Assumptions!F21 | M18: =IFERROR(IF(OR(B18<=0,F18<=0),"N/M",(F18/B18)^(1/4)-1), "N/M") | N18: =IFERROR(IF(OR(G18<=0,K18<=0),"N/M",(K18/G18)^(1/4)-1), "N/M")
A19: Gross profit | B19: =B17-B18 | C19: =C17-C18 | D19: =D17-D18 | E19: =E17-E18 | F19: =F17-F18 | G19: =G17-G18 | H19: =H17-H18 | I19: =I17-I18 | ... K19: =K17-K18 | M19: =IFERROR(IF(OR(B19<=0,F19<=0),"N/M",(F19/B19)^(1/4)-1), "N/M") | N19: =IFERROR(IF(OR(G19<=0,K19<=0),"N/M",(K19/G19)^(1/4)-1), "N/M")
A20: R&D | B20: 1721.2 | C20: 1879 | D20: 2247 | E20: 2464 | F20: 2626 | G20: 2679 | H20: =H17*Assumptions!C25 | I20: =I17*Assumptions!D25 | J20: =J17*Assumptions!E25 | K20: =K17*Assumptions!F25 | M20: =IFERROR(IF(OR(B20<=0,F20<=0),"N/M",(F20/B20)^(1/4)-1), "N/M") | N20: =IFERROR(IF(OR(G20<=0,K20<=0),"N/M",(K20/G20)^(1/4)-1), "N/M")
A21: S&M | B21: 1233.2 | C21: 1462 | D21: 1842 | E21: 2139 | F21: 2432 | G21: 2616 | H21: =H17*Assumptions!C29 | I21: =I17*Assumptions!D29 | J21: =J17*Assumptions!E29 | K21: =K17*Assumptions!F29 | M21: =IFERROR(IF(OR(B21<=0,F21<=0),"N/M",(F21/B21)^(1/4)-1), "N/M") | N21: =IFERROR(IF(OR(G21<=0,K21<=0),"N/M",(K21/G21)^(1/4)-1), "N/M")
A22: G&A | B22: 414.1 | C22: 486 | D22: 599 | E22: 702 | F22: 820 | G22: 912 | H22: =H17*Assumptions!C33 | I22: =I17*Assumptions!D33 | J22: =J17*Assumptions!E33 | K22: =K17*Assumptions!F33 | M22: =IFERROR(IF(OR(B22<=0,F22<=0),"N/M",(F22/B22)^(1/4)-1), "N/M") | N22: =IFERROR(IF(OR(G22<=0,K22<=0),"N/M",(K22/G22)^(1/4)-1), "N/M")
A23: Operating income | B23: -248.6 | C23: -116 | D23: -222 | E23: 183 | F23: 415 | G23: 721 | H23: =H19-H20-H21-H22-280 | I23: =I19-I20-I21-I22-300 | J23: =J19-J20-J21-J22-320 | K23: =K19-K20-K21-K22-340 | M23: =IFERROR(IF(OR(B23<=0,F23<=0),"N/M",(F23/B23)^(1/4)-1), "N/M") | N23: =IFERROR(IF(OR(G23<=0,K23<=0),"N/M",(K23/G23)^(1/4)-1), "N/M")
A24: Operating margin % | B24: =IFERROR(B23/B17,"") | C24: =IFERROR(C23/C17,"") | D24: =IFERROR(D23/D17,"") | E24: =IFERROR(E23/E17,"") | F24: =IFERROR(F23/F17,"") | G24: =IFERROR(G23/G17,"") | H24: =IFERROR(H23/H17,"") | I24: =IFERROR(I23/I17,"") | ... K24: =IFERROR(K23/K17,"") | M24: =IFERROR(F24-B24, "") | N24: =IFERROR(K24-G24, "")
A25: Net income (GAAP) | B25: -282.4 | C25: 29 | D25: -367 | E25: 1381 | F25: 526 | G25: 693 | M25: =IFERROR(IF(OR(B25<=0,F25<=0),"N/M",(F25/B25)^(1/4)-1), "N/M") | N25: =IFERROR(IF(OR(G25<=0,K25<=0),"N/M",(K25/G25)^(1/4)-1), "N/M")
A27: Cash Flow
A28: Cash from operations | B28: 1268.4 | C28: 1651 | D28: 1657 | E28: 2149 | F28: 2461 | G28: 2939 | H28: =H17*Assumptions!C41 | I28: =I17*Assumptions!D41 | J28: =J17*Assumptions!E41 | K28: =K17*Assumptions!F41 | M28: =IFERROR(IF(OR(B28<=0,F28<=0),"N/M",(F28/B28)^(1/4)-1), "N/M") | N28: =IFERROR(IF(OR(G28<=0,K28<=0),"N/M",(K28/G28)^(1/4)-1), "N/M")
A29: Capex (~2% rev) | D29: 364 | E29: 232 | F29: 269 | G29: 162 | H29: =H17*0.02 | I29: =I17*0.02 | J29: =J17*0.02 | K29: =K17*0.02 | M29: =IFERROR(IF(OR(B29<=0,F29<=0),"N/M",(F29/B29)^(1/4)-1), "N/M") | N29: =IFERROR(IF(OR(G29<=0,K29<=0),"N/M",(K29/G29)^(1/4)-1), "N/M")
A30: Free cash flow | B30: =IFERROR(B28-B29,B28) | C30: =IFERROR(C28-C29,C28) | D30: =IFERROR(D28-D29,D28) | E30: =IFERROR(E28-E29,E28) | F30: =IFERROR(F28-F29,F28) | G30: =IFERROR(G28-G29,G28) | H30: =IFERROR(H28-H29,H28) | I30: =IFERROR(I28-I29,I28) | ... K30: =IFERROR(K28-K29,K28) | M30: =IFERROR(IF(OR(B30<=0,F30<=0),"N/M",(F30/B30)^(1/4)-1), "N/M") | N30: =IFERROR(IF(OR(G30<=0,K30<=0),"N/M",(K30/G30)^(1/4)-1), "N/M")
A31: SBC | B31: 1004.9 | C31: 1101 | D31: 1295 | E31: 1416 | F31: 1519 | G31: 1626 | H31: =H17*Assumptions!C37 | I31: =I17*Assumptions!D37 | J31: =J17*Assumptions!E37 | K31: =K17*Assumptions!F37 | M31: =IFERROR(IF(OR(B31<=0,F31<=0),"N/M",(F31/B31)^(1/4)-1), "N/M") | N31: =IFERROR(IF(OR(G31<=0,K31<=0),"N/M",(K31/G31)^(1/4)-1), "N/M")
A32: FCF − SBC | B32: =B30-B31 | C32: =C30-C31 | D32: =D30-D31 | E32: =E30-E31 | F32: =F30-F31 | G32: =G30-G31 | H32: =H30-H31 | I32: =I30-I31 | ... K32: =K30-K31 | M32: =IFERROR(IF(OR(B32<=0,F32<=0),"N/M",(F32/B32)^(1/4)-1), "N/M") | N32: =IFERROR(IF(OR(G32<=0,K32<=0),"N/M",(K32/G32)^(1/4)-1), "N/M")
A34: Per-share
A35: Diluted shares (M) | B35: 237 | C35: 254 | D35: 254.8 | E35: 265.3 | F35: 269.2 | G35: 268.1 | H35: =G35*(1-Assumptions!C45) | I35: =H35*(1-Assumptions!D45) | J35: =I35*(1-Assumptions!E45) | K35: =J35*(1-Assumptions!F45) | M35: =IFERROR(IF(OR(B35<=0,F35<=0),"N/M",(F35/B35)^(1/4)-1), "N/M") | N35: =IFERROR(IF(OR(G35<=0,K35<=0),"N/M",(K35/G35)^(1/4)-1), "N/M")
A36: FCF / share | B36: =IFERROR(B30/B35,"") | C36: =IFERROR(C30/C35,"") | D36: =IFERROR(D30/D35,"") | E36: =IFERROR(E30/E35,"") | F36: =IFERROR(F30/F35,"") | G36: =IFERROR(G30/G35,"") | H36: =IFERROR(H30/H35,"") | I36: =IFERROR(I30/I35,"") | ... K36: =IFERROR(K30/K35,"") | M36: =IFERROR(IF(OR(B36<=0,F36<=0),"N/M",(F36/B36)^(1/4)-1), "N/M") | N36: =IFERROR(IF(OR(G36<=0,K36<=0),"N/M",(K36/G36)^(1/4)-1), "N/M")
A37: 12-mo backlog ($M) | E37: 6602 | F37: 7631 | G37: 8833 | H37: =G37*(1+Assumptions!C17) | I37: =H37*(1+Assumptions!D17) | J37: =I37*(1+Assumptions!E17) | K37: =J37*(1+Assumptions!F17) | M37: =IFERROR(IF(OR(B37<=0,F37<=0),"N/M",(F37/B37)^(1/4)-1), "N/M") | N37: =IFERROR(IF(OR(G37<=0,K37<=0),"N/M",(K37/G37)^(1/4)-1), "N/M")
A39: Valuation (terminal = FY30)
A40: Target ($/sh, ARR-lens) | K40: =(Assumptions!C49*K37+Assumptions!B7*1000)/K35
A41: Target ($/sh, FCF-lens) | K41: =(Assumptions!C52*K30+Assumptions!B7*1000)/K35
A42: Target (blended) | K42: =AVERAGE(K40,K41)

Sheet Valuation
A1: Valuation summary
A3: Scenario | B3: Probability | C3: FY30 target | D3: Return % | E3: IRR (4y) | F3: Prob × target
A4: AI Winner | B4: =Assumptions!C53 | C4: 708.15 | D4: =C4/129.34-1 | E4: =(C4/129.34)^(1/4)-1 | F4: =B4*C4
A5: Run For Cash | B5: =Assumptions!C54 | C5: 124.93 | D5: =C5/129.34-1 | E5: =(C5/129.34)^(1/4)-1 | F5: =B5*C5
A6: Bear | B6: =Assumptions!C55 | C6: 69.15 | D6: =C6/129.34-1 | E6: =(C6/129.34)^(1/4)-1 | F6: =B6*C6
A8: Probability-weighted | C8: =SUM(F4:F6) | D8: =C8/129.34-1 | E8: =(C8/129.34)^(1/4)-1

Sheet Sensitivity
A1: Sensitivity — FCF/share × exit multiple
A3: Target price = FCF/share × multiple. Current price for reference: $129.34
A5: FCF/share ↓ × Mult → | B5: 8× | C5: 12× | D5: 16× | E5: 20× | F5: 24× | G5: 28×
A6: $10 | B6: 80 | C6: 120 | D6: 160 | E6: 200 | F6: 240 | G6: 280
A7: $14 | B7: 112 | C7: 168 | D7: 224 | E7: 280 | F7: 336 | G7: 392
A8: $18 | B8: 144 | C8: 216 | D8: 288 | E8: 360 | F8: 432 | G8: 504
A9: $22 | B9: 176 | C9: 264 | D9: 352 | E9: 440 | F9: 528 | G9: 616
A10: $26 | B10: 208 | C10: 312 | D10: 416 | E10: 520 | F10: 624 | G10: 728
A11: $30 | B11: 240 | C11: 360 | D11: 480 | E11: 600 | F11: 720 | G11: 840

Sheet TSR
A1: Total Shareholder Return decomposition
A2: Entry price $129.34. TSR % = (terminal + cum div) / entry − 1. Buyback retirement value $/sh = cum buyback $$ / horizon shares (how much terminal equity belongs to surviving shareholders by virtue of share retirement).
A4: Scenario | B4: Prob | C4: Horizon | D4: Entry $/sh | E4: Terminal $/sh | F4: Price Δ $/sh | G4: Cum div $/sh | H4: Cum buyback $$M | I4: Implied BB $/surviving sh | J4: Px appr % | K4: Div % | L4: BB accretion % | M4: TSR % | N4: Sum check (Px%+Div%) | O4: IRR % | P4: Entry shares (M) | Q4: Horizon shares (M)
A5: Good AI | B5: 0.35 | C5: 3yr (FY29) | D5: 129.34 | E5: 577.92 | F5: =E5-D5 | G5: 0 | H5: 5652 | I5: 22.52 | J5: =F5/D5 | K5: =G5/D5 | L5: 0.068 | M5: =J5+K5 | N5: =J5+K5 | O5: 0.647 | P5: 268 | Q5: 251
A6: Good AI | B6: 0.35 | C6: 4yr (FY30) | D6: 129.34 | E6: 708.15 | F6: =E6-D6 | G6: 0 | H6: 10044 | I6: 41.05 | J6: =F6/D6 | K6: =G6/D6 | L6: 0.095 | M6: =J6+K6 | N6: =J6+K6 | O6: 0.53 | P6: 268 | Q6: 244.7
A7: Runs For Cash | B7: 0.35 | C7: 3yr (FY29) | D7: 129.34 | E7: 125.26 | F7: =E7-D7 | G7: 11.78 | H7: 6617 | I7: 30.4 | J7: =F7/D7 | K7: =G7/D7 | L7: 0.231 | M7: =J7+K7 | N7: =J7+K7 | O7: 0.019 | P7: 268 | Q7: 217.7
A8: Runs For Cash | B8: 0.35 | C8: 4yr (FY30) | D8: 129.34 | E8: 124.93 | F8: =E8-D8 | G8: 18.94 | H8: 9556 | I8: 48.76 | J8: =F8/D8 | K8: =G8/D8 | L8: 0.367 | M8: =J8+K8 | N8: =J8+K8 | O8: 0.027 | P8: 268 | Q8: 196
A9: What Goes Wrong | B9: 0.3 | C9: 3yr (FY29) | D9: 129.34 | E9: 74.88 | F9: =E9-D9 | G9: 3.39 | H9: 2970 | I9: 12.27 | J9: =F9/D9 | K9: =G9/D9 | L9: 0.107 | M9: =J9+K9 | N9: =J9+K9 | O9: -0.154 | P9: 268 | Q9: 242.1
A10: What Goes Wrong | B10: 0.3 | C10: 4yr (FY30) | D10: 129.34 | E10: 69.15 | F10: =E10-D10 | G10: 5.48 | H10: 3841 | I10: 16.53 | J10: =F10/D10 | K10: =G10/D10 | L10: 0.153 | M10: =J10+K10 | N10: =J10+K10 | O10: -0.128 | P10: 268 | Q10: 232.4
A12: Probability-weighted FY29 TSR | M12: 1.116
A13: Probability-weighted FY30 TSR | M13: 1.479
A15: Reconciliation:
A16: Price Δ % + Cum div % should equal TSR %. Buyback accretion % is attribution-only (already inside terminal price). Implied BB $/surviving sh = cum buyback $$ / horizon shares.

Sheet Drivers
A1: Subscription growth driver decomposition
A2: Splits YoY subscription growth into seats × ARPU, add-on attach, baseline pricing, and the pricing-model transition (consumption credits layered on subscription).
A4: Good AI
A5: FY | B5: Consumption % of sub | C5: Total sub growth % | D5: Seats × ARPU % | E5: Add-on attach % | F5: Baseline pricing % | G5: Consumption uplift % | H5: Sub revenue ($M) | I5: Consumption $ ($M) | J5: Seats × ARPU $ ($M)
A6: FY2027 | B6: 0 | C6: 0.1466 | D6: 0.0733 | E6: 0.044 | F6: 0.0293 | G6: 0 | H6: 10128 | I6: 0 | J6: 647
A7: FY2028 | B7: 0.08 | C7: 0.1333 | D7: 0.0266 | E7: 0.016 | F7: 0.0107 | G7: 0.08 | H7: 11477 | I7: 810 | J7: 270
A8: FY2029 | B8: 0.18 | C8: 0.1266 | D8: 0.0133 | E8: 0.008 | F8: 0.0053 | G8: 0.1 | H8: 12930 | I8: 1148 | J8: 153
A9: FY2030 | B9: 0.3 | C9: 0.1133 | D9: -0.0034 | E9: -0.002 | F9: -0.0013 | G9: 0.12 | H9: 14395 | I9: 1552 | J9: -43
A11: Runs For Cash
A12: FY | B12: Consumption % of sub | C12: Total sub growth % | D12: Seats × ARPU % | E12: Add-on attach % | F12: Baseline pricing % | G12: Consumption uplift % | H12: Sub revenue ($M) | I12: Consumption $ ($M) | J12: Seats × ARPU $ ($M)
A13: FY2027 | B13: 0 | C13: 0.0533 | D13: 0.0267 | E13: 0.016 | F13: 0.0107 | G13: 0 | H13: 9304 | I13: 0 | J13: 236
A14: FY2028 | B14: 0.05 | C14: -0.0333 | D14: -0.0417 | E14: -0.025 | F14: -0.0167 | G14: 0.05 | H14: 8994 | I14: 465 | J14: -388
A15: FY2029 | B15: 0.12 | C15: -0.0933 | D15: -0.0817 | E15: -0.049 | F15: -0.0327 | G15: 0.07 | H15: 8155 | I15: 630 | J15: -734
A16: FY2030 | B16: 0.2 | C16: -0.1 | D16: -0.09 | E16: -0.054 | F16: -0.036 | G16: 0.08 | H16: 7340 | I16: 652 | J16: -734
A18: What Goes Wrong
A19: FY | B19: Consumption % of sub | C19: Total sub growth % | D19: Seats × ARPU % | E19: Add-on attach % | F19: Baseline pricing % | G19: Consumption uplift % | H19: Sub revenue ($M) | I19: Consumption $ ($M) | J19: Seats × ARPU $ ($M)
A20: FY2027 | B20: 0 | C20: -0.0467 | D20: -0.0233 | E20: -0.014 | F20: -0.0093 | G20: 0 | H20: 8421 | I20: 0 | J20: -206
A21: FY2028 | B21: 0.03 | C21: -0.0967 | D21: -0.0633 | E21: -0.038 | F21: -0.0253 | G21: 0.03 | H21: 7607 | I21: 253 | J21: -533
A22: FY2029 | B22: 0.08 | C22: -0.1067 | D22: -0.0783 | E22: -0.047 | F22: -0.0313 | G22: 0.05 | H22: 6796 | I22: 380 | J22: -596
A23: FY2030 | B23: 0.15 | C23: -0.0967 | D23: -0.0833 | E23: -0.05 | F23: -0.0333 | G23: 0.07 | H23: 6139 | I23: 476 | J23: -566

Sheet Sens_SBC
A1: SBC compression × exit multiple → FY30 share price
A2: SBC % of revenue (FY30) ↓ × FCF exit multiple →
A4: SBC % of revenue (FY30) ↓ | B4: 16× | C4: 18× | D4: 20× | E4: 22× | F4: 24× | G4: 26×
A5: +16% | B5: 240.44 | C5: 269.67 | D5: 298.9 | E5: 328.13 | F5: 357.36 | G5: 386.58
A6: +14% | B6: 262.72 | C6: 294.73 | D6: 326.74 | E6: 358.75 | F6: 390.76 | G6: 422.78
A7: +12% | B7: 284.99 | C7: 319.78 | D7: 354.58 | E7: 389.38 | F7: 424.17 | G7: 458.97
A8: +10% | B8: 307.26 | C8: 344.84 | D8: 382.42 | E8: 420 | F8: 457.58 | G8: 495.16
A9: +8% | B9: 329.53 | C9: 369.9 | D9: 410.26 | E9: 450.62 | F9: 490.99 | G9: 531.35

Sheet Sens_Growth
A1: Subscription growth × exit multiple → FY30 share price
A2: 4-yr subscription growth CAGR ↓ × FCF exit multiple →
A4: 4-yr subscription growth CAGR ↓ | B4: 10× | C4: 14× | D4: 18× | E4: 22× | F4: 26× | G4: 30×
A5: -5% | B5: 117.9 | C5: 162.41 | D5: 206.93 | E5: 251.44 | F5: 295.95 | G5: 340.46
A6: +0% | B6: 143.24 | C6: 197.89 | D6: 252.54 | E6: 307.19 | F6: 361.84 | G6: 416.49
A7: +5% | B7: 172.69 | C7: 239.12 | D7: 305.54 | E7: 371.97 | F7: 438.4 | G7: 504.82
A8: +10% | B8: 206.65 | C8: 286.66 | D8: 366.68 | E8: 446.69 | F8: 526.7 | G8: 606.72
A9: +15% | B9: 245.58 | C9: 341.16 | D9: 436.74 | E9: 532.33 | F9: 627.91 | G9: 723.49
A10: +20% | B10: 289.92 | C10: 403.25 | D10: 516.57 | E10: 629.89 | F10: 743.21 | G10: 856.53

Sheet Sens_Pricing
A1: Pricing transition × FY30 FCF margin → FY30 FCF/share
A2: Consumption % of subscription (FY30) ↓ × FCF margin →
A4: Consumption % of subscription (FY30) ↓ | B4: +25% | C4: +30% | D4: +33% | E4: +36% | F4: +39% | G4: +42%
A5: +0% | B5: 17.02 | C5: 20.42 | D5: 22.46 | E5: 24.5 | F5: 26.55 | G5: 28.59
A6: +10% | B6: 18.65 | C6: 22.38 | D6: 24.62 | E6: 26.86 | F6: 29.1 | G6: 31.33
A7: +20% | B7: 20.29 | C7: 24.34 | D7: 26.78 | E7: 29.21 | F7: 31.65 | G7: 34.08
A8: +30% | B8: 21.92 | C8: 26.3 | D8: 28.93 | E8: 31.56 | F8: 34.19 | G8: 36.82
A9: +40% | B9: 23.55 | C9: 28.26 | D9: 31.09 | E9: 33.92 | F9: 36.74 | G9: 39.57

Sheet Revenue_Build
A1: Four-stream revenue build (HCM ARR / Financials ARR / AI ARR / Services)
A3: FY26 base ($M): | B3: HCM $5,629 | Financials $2,804 | AI ARR $400 | Services $719 | Total $9,552
A5: Good AI
A6: $M unless noted | B6: FY27 | C6: FY28 | D6: FY29 | E6: FY30
A7: HCM ARR | B7: 5930 | C7: 6374 | D7: 6922 | E7: 7491
A8: Financials ARR | B8: 3360 | C8: 4050 | D8: 4830 | E8: 5676
A9: AI ARR booked | B9: 800 | C9: 1440 | D9: 2304 | E9: 3226
A10: AI ARR recognized | B10: 560 | C10: 1200 | D10: 2143 | E10: 3152
A11: AI deferred balance | B11: 240 | C11: 480 | D11: 641 | E11: 714
A12: Services | B12: 712 | C12: 698 | D12: 698 | E12: 712
A13: Total revenue | B13: 10561 | C13: 12322 | D13: 14593 | E13: 17031
A14: HCM ARR GM % | B14: 0.84 | C14: 0.84 | D14: 0.84 | E14: 0.84
A15: Financials GM % | B15: 0.8 | C15: 0.81 | D15: 0.82 | E15: 0.83
A16: AI ARR GM % | B16: 0.5 | C16: 0.55 | D16: 0.6 | E16: 0.65
A17: Services GM % | B17: -0.1 | C17: -0.08 | D17: -0.05 | E17: -0.02
A18: Blended GM % | B18: 0.7459 | C18: 0.7498 | D18: 0.7556 | E18: 0.7656
... A23: Total GP | B23: 7878 | C23: 9239 | D23: 11026 | E23: 13038
A25: Runs For Cash
A26: $M unless noted | B26: FY27 | C26: FY28 | D26: FY29 | E26: FY30
A27: HCM ARR | B27: 5867 | C27: 5663 | D27: 5370 | E27: 5040
A28: Financials ARR | B28: 2812 | C28: 2621 | D28: 2236 | E28: 1948
A29: AI ARR booked | B29: 520 | C29: 598 | D29: 628 | E29: 628
A30: AI ARR recognized | B30: 416 | C30: 560 | D30: 662 | E30: 641
A31: AI deferred balance | B31: 104 | C31: 142 | D31: 108 | E31: 94
A32: Services | B32: 697 | C32: 628 | D32: 552 | E32: 486
A33: Total revenue | B33: 9793 | C33: 9472 | D33: 8821 | E33: 8115
A34: HCM ARR GM % | B34: 0.84 | C34: 0.84 | D34: 0.84 | E34: 0.84
A35: Financials GM % | B35: 0.8 | C35: 0.81 | D35: 0.82 | E35: 0.83
A36: AI ARR GM % | B36: 0.45 | C36: 0.45 | D36: 0.45 | E36: 0.45
A37: Services GM % | B37: -0.1 | C37: -0.12 | D37: -0.13 | E37: -0.15
A38: Blended GM % | B38: 0.745 | C38: 0.745 | D38: 0.7449 | E38: 0.7475
... A43: Total GP | B43: 7296 | C43: 7057 | D43: 6571 | E43: 6066
A45: What Goes Wrong
A46: $M unless noted | B46: FY27 | C46: FY28 | D46: FY29 | E46: FY30
A47: HCM ARR | B47: 5652 | C47: 5233 | D47: 4795 | E47: 4376
A48: Financials ARR | B48: 2640 | C48: 2310 | D48: 1950 | E48: 1656
A49: AI ARR booked | B49: 480 | C49: 528 | D49: 554 | E49: 554
A50: AI ARR recognized | B50: 408 | C50: 511 | D50: 589 | E50: 567
A51: AI deferred balance | B51: 72 | C51: 89 | D51: 54 | E51: 42
A52: Services | B52: 647 | C52: 550 | D52: 468 | E52: 411
...

Sheet AI_Deferred
A1: AI ARR — booked vs recognized (deferred-revenue mechanic)
A2: AI ARR has a per-year deferred fraction. Deferred dollars sit on the balance sheet and are recognized ratably over the next two years (50%/50%). Total revenue uses RECOGNIZED, not booked.
A3: FY26 base AI ARR: $400M (per Q4 FY26 prepared remarks)
A5: Good AI
A6: $M / % | B6: FY27 | C6: FY28 | D6: FY29 | E6: FY30
A7: Booked growth % | B7: 1 | C7: 0.8 | D7: 0.6 | E7: 0.4
A8: Deferred fraction % | B8: 0.3 | C8: 0.25 | D8: 0.2 | E8: 0.15
A9: AI ARR booked ($M) | B9: 800 | C9: 1440 | D9: 2304 | E9: 3226
A10: AI ARR recognized ($M) | B10: 560 | C10: 1200 | D10: 2143 | E10: 3152
A11: Deferred balance ($M) | B11: 240 | C11: 480 | D11: 641 | E11: 714
A12: Booked − Recognized | B12: 240 | C12: 240 | D12: 161 | E12: 74
A14: Runs For Cash
A15: $M / % | B15: FY27 | C15: FY28 | D15: FY29 | E15: FY30
A16: Booked growth % | B16: 0.3 | C16: 0.15 | D16: 0.05 | E16: 0
A17: Deferred fraction % | B17: 0.2 | C17: 0.15 | D17: 0.1 | E17: 0.1
A18: AI ARR booked ($M) | B18: 520 | C18: 598 | D18: 628 | E18: 628
A19: AI ARR recognized ($M) | B19: 416 | C19: 560 | D19: 662 | E19: 641
A20: Deferred balance ($M) | B20: 104 | C20: 142 | D20: 108 | E20: 94
A21: Booked − Recognized | B21: 104 | C21: 38 | D21: -34 | E21: -13
A23: What Goes Wrong
A24: $M / % | B24: FY27 | C24: FY28 | D24: FY29 | E24: FY30
A25: Booked growth % | B25: 0.2 | C25: 0.1 | D25: 0.05 | E25: 0
A26: Deferred fraction % | B26: 0.15 | C26: 0.1 | D26: 0.05 | E26: 0.05
A27: AI ARR booked ($M) | B27: 480 | C27: 528 | D27: 554 | E27: 554
A28: AI ARR recognized ($M) | B28: 408 | C28: 511 | D28: 589 | E28: 567
A29: Deferred balance ($M) | B29: 72 | C29: 89 | D29: 54 | E29: 42
A30: Booked − Recognized | B30: 72 | C30: 17 | D30: -35 | E30: -13

Sheet 3Stmt_AI
A1: WDAY three-statement model — Good AI
A2: Full IS / BS / CF rolled forward from FY26 10-K actuals. BS must balance: Total Assets = Total Liabilities + Equity (check row at bottom of BS).
A4: $M unless noted | B4: FY26A | C4: FY27E | D4: FY28E | E4: FY29E | F4: FY30E
A5: INCOME STATEMENT
A6: HCM ARR | B6: 5629 | C6: 5930 | D6: 6374 | E6: 6922 | F6: 7491
A7: Financials ARR | B7: 2804 | C7: 3360 | D7: 4050 | E7: 4830 | F7: 5676
A8: AI ARR (recognized) | B8: 400 | C8: 560 | D8: 1200 | E8: 2143 | F8: 3152
A9: Services | B9: 719 | C9: 712 | D9: 698 | E9: 698 | F9: 712
A10: Total revenue | B10: 9552 | C10: 10561 | D10: 12322 | E10: 14593 | F10: 17031
A11: Cost of revenue | B11: 2624 | C11: 2683 | D11: 3083 | E11: 3567 | F11: 3993
A12: Gross profit | B12: 6928 | C12: 7878 | D12: 9239 | E12: 11026 | F12: 13038
A13: R&D | B13: 2679 | C13: 2746 | D13: 3080 | E13: 3502 | F13: 3917
A14: S&M | B14: 2616 | C14: 2640 | D14: 2834 | E14: 3064 | F14: 3406
A15: G&A | B15: 912 | C15: 951 | D15: 1047 | E15: 1167 | F15: 1362
A16: Operating income | B16: 721 | C16: 1231 | D16: 1916 | E16: 2864 | F16: 3853
A17: Operating margin % | B17: 0.075481575 | C17: 0.1166 | D17: 0.1555 | E17: 0.1963 | F17: 0.2263
... A24: Diluted EPS | B24: 2.59 | C24: 3.84 | D24: 6.21 | E24: 9.49 | F24: 12.99
A26: BALANCE SHEET
A27: ASSETS
A28: Cash & equivalents | B28: 1501 | C28: 3699 | D28: 6063 | E28: 7783 | F28: 9227
A29: Marketable securities | B29: 3942 | C29: 3942 | D29: 3942 | E29: 3942 | F29: 3942
A30: Accounts receivable | B30: 2332 | C30: 2578 | D30: 3008 | E30: 3563 | F30: 4158
A31: Prepaid + other current | B31: 348 | C31: 380 | D31: 444 | E31: 525 | F31: 613
A32: Deferred costs (current) | B32: 306 | C32: 338 | D32: 394 | E32: 467 | F32: 545
A33: Property, plant & equipment | B33: 1093 | C33: 1067 | D33: 1061 | E33: 1086 | F33: 1145
A34: Operating lease ROU | B34: 719 | C34: 719 | D34: 719 | E34: 719 | F34: 719
A35: Goodwill | B35: 5229 | C35: 5229 | D35: 5229 | E35: 5229 | F35: 5229
A36: Intangibles (net) | B36: 600 | C36: 500 | D36: 400 | E36: 300 | F36: 200
A37: Deferred contract costs (NC) | B37: 634 | C37: 697 | D37: 813 | E37: 963 | F37: 1124
A38: Deferred tax assets | B38: 829 | C38: 829 | D38: 829 | E38: 829 | F38: 829
A39: Other assets (NC) | B39: 541 | C39: 541 | D39: 541 | E39: 541 | F39: 541
A40: Total assets | B40: 18074 | C40: 20520 | D40: 23444 | E40: 25948 | F40: 28273
A42: LIABILITIES
A43: Accounts payable | B43: 142 | C43: 158 | D43: 185 | E43: 219 | F43: 255
A44: Accrued compensation | B44: 642 | C44: 718 | D44: 838 | E44: 992 | F44: 1158
A45: Accrued other | B45: 454 | C45: 507 | D45: 591 | E45: 700 | F45: 817
A46: Deferred revenue (current) | B46: 5010 | C46: 5411 | D46: 6583 | E46: 7936 | F46: 9281
A47: Deferred revenue (NC) | B47: 71 | C47: 71 | D47: 71 | E47: 71 | F47: 71
A48: Operating lease liab (current) | B48: 130 | C48: 130 | D48: 130 | E48: 130 | F48: 130
A49: Operating lease liab (NC) | B49: 704 | C49: 704 | D49: 704 | E49: 704 | F49: 704
...

Sheet 3Stmt_Cash
A1: WDAY three-statement model — Runs For Cash
A2: Full IS / BS / CF rolled forward from FY26 10-K actuals. BS must balance: Total Assets = Total Liabilities + Equity (check row at bottom of BS).
A4: $M unless noted | B4: FY26A | C4: FY27E | D4: FY28E | E4: FY29E | F4: FY30E
A5: INCOME STATEMENT
A6: HCM ARR | B6: 5629 | C6: 5867 | D6: 5663 | E6: 5370 | F6: 5040
A7: Financials ARR | B7: 2804 | C7: 2812 | D7: 2621 | E7: 2236 | F7: 1948
A8: AI ARR (recognized) | B8: 400 | C8: 416 | D8: 560 | E8: 662 | F8: 641
A9: Services | B9: 719 | C9: 697 | D9: 628 | E9: 552 | F9: 486
A10: Total revenue | B10: 9552 | C10: 9793 | D10: 9472 | E10: 8821 | F10: 8115
A11: Cost of revenue | B11: 2624 | C11: 2497 | D11: 2415 | E11: 2250 | F11: 2049
A12: Gross profit | B12: 6928 | C12: 7296 | D12: 7057 | E12: 6571 | F12: 6066
A13: R&D | B13: 2679 | C13: 2350 | D13: 1894 | E13: 1411 | F13: 1055
A14: S&M | B14: 2616 | C14: 2154 | D14: 1610 | E14: 1147 | F14: 811
A15: G&A | B15: 912 | C15: 783 | D15: 663 | E15: 529 | F15: 406
A16: Operating income | B16: 721 | C16: 1721 | D16: 2611 | E16: 3225 | F16: 3556
A17: Operating margin % | B17: 0.075481575 | C17: 0.1757 | D17: 0.2757 | E17: 0.3656 | F17: 0.4382
... A24: Diluted EPS | B24: 2.59 | C24: 5.35 | D24: 8.71 | E24: 11.65 | F24: 14
A26: BALANCE SHEET
A27: ASSETS
A28: Cash & equivalents | B28: 1501 | C28: 2430 | D28: 2024 | E28: 738 | F28: -646
A29: Marketable securities | B29: 3942 | C29: 3942 | D29: 3942 | E29: 3942 | F29: 3942
A30: Accounts receivable | B30: 2332 | C30: 2391 | D30: 2312 | E30: 2154 | F30: 1981
A31: Prepaid + other current | B31: 348 | C31: 353 | D31: 341 | E31: 318 | F31: 292
A32: Deferred costs (current) | B32: 306 | C32: 313 | D32: 303 | E32: 282 | F32: 260
A33: Property, plant & equipment | B33: 1093 | C33: 1052 | D33: 989 | E33: 898 | F33: 778
A34: Operating lease ROU | B34: 719 | C34: 719 | D34: 719 | E34: 719 | F34: 719
A35: Goodwill | B35: 5229 | C35: 5229 | D35: 5229 | E35: 5229 | F35: 5229
A36: Intangibles (net) | B36: 600 | C36: 500 | D36: 400 | E36: 300 | F36: 200
A37: Deferred contract costs (NC) | B37: 634 | C37: 646 | D37: 625 | E37: 582 | F37: 536
A38: Deferred tax assets | B38: 829 | C38: 829 | D38: 829 | E38: 829 | F38: 829
A39: Other assets (NC) | B39: 541 | C39: 541 | D39: 541 | E39: 541 | F39: 541
A40: Total assets | B40: 18074 | C40: 18945 | D40: 18255 | E40: 16531 | F40: 14660
A42: LIABILITIES
A43: Accounts payable | B43: 142 | C43: 147 | D43: 142 | E43: 132 | F43: 122
A44: Accrued compensation | B44: 642 | C44: 666 | D44: 644 | E44: 600 | F44: 552
A45: Accrued other | B45: 454 | C45: 470 | D45: 455 | E45: 423 | F45: 390
A46: Deferred revenue (current) | B46: 5010 | C46: 4879 | D46: 4785 | E46: 4449 | F46: 4099
A47: Deferred revenue (NC) | B47: 71 | C47: 71 | D47: 71 | E47: 71 | F47: 71
A48: Operating lease liab (current) | B48: 130 | C48: 130 | D48: 130 | E48: 130 | F48: 130
A49: Operating lease liab (NC) | B49: 704 | C49: 704 | D49: 704 | E49: 704 | F49: 704
...

Sheet 3Stmt_Bear
A1: WDAY three-statement model — What Goes Wrong
A2: Full IS / BS / CF rolled forward from FY26 10-K actuals. BS must balance: Total Assets = Total Liabilities + Equity (check row at bottom of BS).
A4: $M unless noted | B4: FY26A | C4: FY27E | D4: FY28E | E4: FY29E | F4: FY30E
A5: INCOME STATEMENT
A6: HCM ARR | B6: 5629 | C6: 5652 | D6: 5233 | E6: 4795 | F6: 4376
A7: Financials ARR | B7: 2804 | C7: 2640 | D7: 2310 | E7: 1950 | F7: 1656
A8: AI ARR (recognized) | B8: 400 | C8: 408 | D8: 511 | E8: 589 | F8: 567
A9: Services | B9: 719 | C9: 647 | D9: 550 | E9: 468 | F9: 411
A10: Total revenue | B10: 9552 | C10: 9347 | D10: 8604 | E10: 7802 | F10: 7010
A11: Cost of revenue | B11: 2624 | C11: 2389 | D11: 2205 | E11: 2014 | F11: 1807
A12: Gross profit | B12: 6928 | C12: 6958 | D12: 6399 | E12: 5788 | F12: 5203
A13: R&D | B13: 2679 | C13: 2430 | D13: 1979 | E13: 1560 | F13: 1262
A14: S&M | B14: 2616 | C14: 2243 | D14: 1807 | E14: 1404 | F14: 1122
A15: G&A | B15: 912 | C15: 841 | D15: 688 | E15: 585 | F15: 491
A16: Operating income | B16: 721 | C16: 1169 | D16: 1673 | E16: 2009 | F16: 2123
A17: Operating margin % | B17: 0.075481575 | C17: 0.1251 | D17: 0.1945 | E17: 0.2575 | F17: 0.3029
... A24: Diluted EPS | B24: 2.59 | C24: 3.68 | D24: 5.52 | E24: 6.91 | F24: 7.63
A26: BALANCE SHEET
A27: ASSETS
A28: Cash & equivalents | B28: 1501 | C28: 2850 | D28: 3977 | E28: 4958 | F28: 6097
A29: Marketable securities | B29: 3942 | C29: 3942 | D29: 3942 | E29: 3942 | F29: 3942
A30: Accounts receivable | B30: 2332 | C30: 2282 | D30: 2101 | E30: 1905 | F30: 1711
A31: Prepaid + other current | B31: 348 | C31: 336 | D31: 310 | E31: 281 | F31: 252
A32: Deferred costs (current) | B32: 306 | C32: 299 | D32: 275 | E32: 250 | F32: 224
A33: Property, plant & equipment | B33: 1093 | C33: 1043 | D33: 963 | E33: 852 | F33: 710
A34: Operating lease ROU | B34: 719 | C34: 719 | D34: 719 | E34: 719 | F34: 719
A35: Goodwill | B35: 5229 | C35: 5229 | D35: 5229 | E35: 5229 | F35: 5229
A36: Intangibles (net) | B36: 600 | C36: 500 | D36: 400 | E36: 300 | F36: 200
A37: Deferred contract costs (NC) | B37: 634 | C37: 617 | D37: 568 | E37: 515 | F37: 463
A38: Deferred tax assets | B38: 829 | C38: 829 | D38: 829 | E38: 829 | F38: 829
A39: Other assets (NC) | B39: 541 | C39: 541 | D39: 541 | E39: 541 | F39: 541
A40: Total assets | B40: 18074 | C40: 19187 | D40: 19853 | E40: 20320 | F40: 20918
A42: LIABILITIES
A43: Accounts payable | B43: 142 | C43: 140 | D43: 129 | E43: 117 | F43: 105
A44: Accrued compensation | B44: 642 | C44: 636 | D44: 585 | E44: 531 | F44: 477
A45: Accrued other | B45: 454 | C45: 449 | D45: 413 | E45: 374 | F45: 336
A46: Deferred revenue (current) | B46: 5010 | C46: 4640 | D46: 4317 | E46: 3904 | F46: 3506
A47: Deferred revenue (NC) | B47: 71 | C47: 71 | D47: 71 | E47: 71 | F47: 71
A48: Operating lease liab (current) | B48: 130 | C48: 130 | D48: 130 | E48: 130 | F48: 130
A49: Operating lease liab (NC) | B49: 704 | C49: 704 | D49: 704 | E49: 704 | F49: 704
...

Sheet Unit_Economics
A1: Unit economics — HCM (seats × PEPM × 12) and Financials (customers × ARPC)
A2: HCM revenue ($M) = seats(M) × PEPM($/mo) × 12. Financials revenue ($M) = customers(#) × ARPC($k/yr) / 1000. All historical values are TRIANGULATED ESTIMATES from WDAY disclosures.
A3: Reconciliation check: implied revenue should equal the HCM ARR / Financials ARR lines in the Revenue_Build tab (they're computed from the same seats × PEPM math).
A5: Historical (FY18-FY26, estimates)
A6: $M / seats / customers | B6: FY2018 | C6: FY2019 | D6: FY2020 | E6: FY2021 | F6: FY2022 | G6: FY2023 | H6: FY2024 | I6: FY2025 | J6: FY2026
A7: HCM seats (M) | B7: 18.5 | C7: 22 | D7: 26 | E7: 29.5 | F7: 34 | G7: 40 | H7: 47 | I7: 53 | J7: 60
A8: HCM PEPM ($/mo) | B8: 8.74 | C8: 9.44 | D8: 9.8 | E8: 9.88 | F8: 10.17 | G8: 10.29 | H8: 9.13 | I8: 9.24 | J8: 7.82
A9: HCM revenue = seats × PEPM × 12 ($M) | B9: =B7*B8*12 | C9: =C7*C8*12 | D9: =D7*D8*12 | E9: =E7*E8*12 | F9: =F7*F8*12 | G9: =G7*G8*12 | H9: =H7*H8*12 | I9: =I7*I8*12 | J9: =J7*J8*12
A11: Financials customers (#) | B11: 380 | C11: 490 | D11: 620 | E11: 770 | F11: 960 | G11: 1200 | H11: 1500 | I11: 1800 | J11: 2150
A12: Financials ARPC ($k/yr) | B12: 405 | C12: 462 | D12: 528 | E12: 599 | F12: 678 | G12: 808 | H12: 969 | I12: 965 | J12: 1304
A13: Financials revenue = customers × ARPC / 1000 ($M) | B13: =B11*B12/1000 | C13: =C11*C12/1000 | D13: =D11*D12/1000 | E13: =E11*E12/1000 | F13: =F11*F12/1000 | G13: =G11*G12/1000 | H13: =H11*H12/1000 | I13: =I11*I12/1000 | J13: =J11*J12/1000
A16: Forecast (FY27-FY30) per scenario
A17: Good AI
A18: $M / seats / customers | B18: FY2027 | C18: FY2028 | D18: FY2029 | E18: FY2030
A19: HCM seats (M) | B19: 62 | C19: 64 | D19: 66 | E19: 68
A20: HCM PEPM ($/mo) | B20: 7.97 | C20: 8.3 | D20: 8.74 | E20: 9.18
A21: HCM revenue = seats × PEPM × 12 ($M) | B21: =B19*B20*12 | C21: =C19*C20*12 | D21: =D19*D20*12 | E21: =E19*E20*12
A22: HCM ARR from model ($M) | B22: 5930 | C22: 6374 | D22: 6922 | E22: 7491
A23: Check: implied − HCM ARR ($M, should ≈ 0) | B23: =B21-B22 | C23: =C21-C22 | D23: =D21-D22 | E23: =E21-E22
A25: Financials customers (#) | B25: 2400 | C25: 2700 | D25: 3000 | E25: 3300
A26: Financials ARPC ($k/yr) | B26: 1400 | C26: 1500 | D26: 1610 | E26: 1720
A27: Financials revenue = customers × ARPC / 1000 ($M) | B27: =B25*B26/1000 | C27: =C25*C26/1000 | D27: =D25*D26/1000 | E27: =E25*E26/1000
A28: Financials ARR from model ($M) | B28: 3360 | C28: 4050 | D28: 4830 | E28: 5676
A29: Check: implied − Fin ARR ($M, should ≈ 0) | B29: =B27-B28 | C29: =C27-C28 | D29: =D27-D28 | E29: =E27-E28
A32: Runs For Cash
A33: $M / seats / customers | B33: FY2027 | C33: FY2028 | D33: FY2029 | E33: FY2030
A34: HCM seats (M) | B34: 61.5 | C34: 60.5 | D34: 58.5 | E34: 56
A35: HCM PEPM ($/mo) | B35: 7.95 | C35: 7.8 | D35: 7.65 | E35: 7.5
A36: HCM revenue = seats × PEPM × 12 ($M) | B36: =B34*B35*12 | C36: =C34*C35*12 | D36: =D34*D35*12 | E36: =E34*E35*12
A37: HCM ARR from model ($M) | B37: 5867 | C37: 5663 | D37: 5370 | E37: 5040
A38: Check: implied − HCM ARR ($M, should ≈ 0) | B38: =B36-B37 | C38: =C36-C37 | D38: =D36-D37 | E38: =E36-E37
A40: Financials customers (#) | B40: 2250 | C40: 2250 | D40: 2150 | E40: 2050
A41: Financials ARPC ($k/yr) | B41: 1250 | C41: 1165 | D41: 1040 | E41: 950
A42: Financials revenue = customers × ARPC / 1000 ($M) | B42: =B40*B41/1000 | C42: =C40*C41/1000 | D42: =D40*D41/1000 | E42: =E40*E41/1000
A43: Financials ARR from model ($M) | B43: 2812 | C43: 2621 | D43: 2236 | E43: 1948
A44: Check: implied − Fin ARR ($M, should ≈ 0) | B44: =B42-B43 | C44: =C42-C43 | D44: =D42-D43 | E44: =E42-E43
A47: What Goes Wrong
A48: $M / seats / customers | B48: FY2027 | C48: FY2028 | D48: FY2029 | E48: FY2030
A49: HCM seats (M) | B49: 60 | C49: 57 | D49: 54 | E49: 51
A50: HCM PEPM ($/mo) | B50: 7.85 | C50: 7.65 | D50: 7.4 | E50: 7.15
...
